Workbook

Sheet START HERE
A1: MICHAEL BID INTELLIGENCE PORTFOLIO | B1: MICHAEL BID INTELLIGENCE PORTFOLIO | C1: MICHAEL BID INTELLIGENCE PORTFOLIO | D1: MICHAEL BID INTELLIGENCE PORTFOLIO | E1: MICHAEL BID INTELLIGENCE PORTFOLIO | F1: MICHAEL BID INTELLIGENCE PORTFOLIO | G1: MICHAEL BID INTELLIGENCE PORTFOLIO | H1: MICHAEL BID INTELLIGENCE PORTFOLIO
A2: Interactive fictional bid-management and business-intelligence demonstration | Created for Michael Ngo | B2: Interactive fictional bid-management and business-intelligence demonstration | Created for Michael Ngo | C2: Interactive fictional bid-management and business-intelligence demonstration | Created for Michael Ngo | D2: Interactive fictional bid-management and business-intelligence demonstration | Created for Michael Ngo | E2: Interactive fictional bid-management and business-intelligence demonstration | Created for Michael Ngo | F2: Interactive fictional bid-management and business-intelligence demonstration | Created for Michael Ngo | G2: Interactive fictional bid-management and business-intelligence demonstration | Created for Michael Ngo | H2: Interactive fictional bid-management and business-intelligence demonstration | Created for Michael Ngo
A5: CONFIDENTIALITY NOTICE | B5: CONFIDENTIALITY NOTICE | C5: CONFIDENTIALITY NOTICE | D5: CONFIDENTIALITY NOTICE | E5: CONFIDENTIALITY NOTICE | F5: CONFIDENTIALITY NOTICE | G5: CONFIDENTIALITY NOTICE | H5: CONFIDENTIALITY NOTICE
A6: This workbook uses an entirely fictional dataset. Names, prices, opportunities, outcomes, contacts, and narratives were created as an original portfolio demonstration and do not reproduce employer data. | B6: This workbook uses an entirely fictional dataset. Names, prices, opportunities, outcomes, contacts, and narratives were created as an original portfolio demonstration and do not reproduce employer data. | C6: This workbook uses an entirely fictional dataset. Names, prices, opportunities, outcomes, contacts, and narratives were created as an original portfolio demonstration and do not reproduce employer data. | D6: This workbook uses an entirely fictional dataset. Names, prices, opportunities, outcomes, contacts, and narratives were created as an original portfolio demonstration and do not reproduce employer data. | E6: This workbook uses an entirely fictional dataset. Names, prices, opportunities, outcomes, contacts, and narratives were created as an original portfolio demonstration and do not reproduce employer data. | F6: This workbook uses an entirely fictional dataset. Names, prices, opportunities, outcomes, contacts, and narratives were created as an original portfolio demonstration and do not reproduce employer data. | G6: This workbook uses an entirely fictional dataset. Names, prices, opportunities, outcomes, contacts, and narratives were created as an original portfolio demonstration and do not reproduce employer data. | H6: This workbook uses an entirely fictional dataset. Names, prices, opportunities, outcomes, contacts, and narratives were created as an original portfolio demonstration and do not reproduce employer data.
A7: This workbook uses an entirely fictional dataset. Names, prices, opportunities, outcomes, contacts, and narratives were created as an original portfolio demonstration and do not reproduce employer data. | B7: This workbook uses an entirely fictional dataset. Names, prices, opportunities, outcomes, contacts, and narratives were created as an original portfolio demonstration and do not reproduce employer data. | C7: This workbook uses an entirely fictional dataset. Names, prices, opportunities, outcomes, contacts, and narratives were created as an original portfolio demonstration and do not reproduce employer data. | D7: This workbook uses an entirely fictional dataset. Names, prices, opportunities, outcomes, contacts, and narratives were created as an original portfolio demonstration and do not reproduce employer data. | E7: This workbook uses an entirely fictional dataset. Names, prices, opportunities, outcomes, contacts, and narratives were created as an original portfolio demonstration and do not reproduce employer data. | F7: This workbook uses an entirely fictional dataset. Names, prices, opportunities, outcomes, contacts, and narratives were created as an original portfolio demonstration and do not reproduce employer data. | G7: This workbook uses an entirely fictional dataset. Names, prices, opportunities, outcomes, contacts, and narratives were created as an original portfolio demonstration and do not reproduce employer data. | H7: This workbook uses an entirely fictional dataset. Names, prices, opportunities, outcomes, contacts, and narratives were created as an original portfolio demonstration and do not reproduce employer data.
A9: BUSINESS PROBLEM | B9: BUSINESS PROBLEM | C9: BUSINESS PROBLEM | D9: BUSINESS PROBLEM | E9: BUSINESS PROBLEM | F9: BUSINESS PROBLEM | G9: BUSINESS PROBLEM | H9: BUSINESS PROBLEM
A10: Opportunity information often arrives through disconnected portals, emails, documents, and internal conversations. Without a structured system, leadership cannot reliably measure workload, pursuit quality, bottlenecks, pricing performance, or decision outcomes. | B10: Opportunity information often arrives through disconnected portals, emails, documents, and internal conversations. Without a structured system, leadership cannot reliably measure workload, pursuit quality, bottlenecks, pricing performance, or decision outcomes. | C10: Opportunity information often arrives through disconnected portals, emails, documents, and internal conversations. Without a structured system, leadership cannot reliably measure workload, pursuit quality, bottlenecks, pricing performance, or decision outcomes. | D10: Opportunity information often arrives through disconnected portals, emails, documents, and internal conversations. Without a structured system, leadership cannot reliably measure workload, pursuit quality, bottlenecks, pricing performance, or decision outcomes. | E10: Opportunity information often arrives through disconnected portals, emails, documents, and internal conversations. Without a structured system, leadership cannot reliably measure workload, pursuit quality, bottlenecks, pricing performance, or decision outcomes. | F10: Opportunity information often arrives through disconnected portals, emails, documents, and internal conversations. Without a structured system, leadership cannot reliably measure workload, pursuit quality, bottlenecks, pricing performance, or decision outcomes. | G10: Opportunity information often arrives through disconnected portals, emails, documents, and internal conversations. Without a structured system, leadership cannot reliably measure workload, pursuit quality, bottlenecks, pricing performance, or decision outcomes. | H10: Opportunity information often arrives through disconnected portals, emails, documents, and internal conversations. Without a structured system, leadership cannot reliably measure workload, pursuit quality, bottlenecks, pricing performance, or decision outcomes.
A11: Opportunity information often arrives through disconnected portals, emails, documents, and internal conversations. Without a structured system, leadership cannot reliably measure workload, pursuit quality, bottlenecks, pricing performance, or decision outcomes. | B11: Opportunity information often arrives through disconnected portals, emails, documents, and internal conversations. Without a structured system, leadership cannot reliably measure workload, pursuit quality, bottlenecks, pricing performance, or decision outcomes. | C11: Opportunity information often arrives through disconnected portals, emails, documents, and internal conversations. Without a structured system, leadership cannot reliably measure workload, pursuit quality, bottlenecks, pricing performance, or decision outcomes. | D11: Opportunity information often arrives through disconnected portals, emails, documents, and internal conversations. Without a structured system, leadership cannot reliably measure workload, pursuit quality, bottlenecks, pricing performance, or decision outcomes. | E11: Opportunity information often arrives through disconnected portals, emails, documents, and internal conversations. Without a structured system, leadership cannot reliably measure workload, pursuit quality, bottlenecks, pricing performance, or decision outcomes. | F11: Opportunity information often arrives through disconnected portals, emails, documents, and internal conversations. Without a structured system, leadership cannot reliably measure workload, pursuit quality, bottlenecks, pricing performance, or decision outcomes. | G11: Opportunity information often arrives through disconnected portals, emails, documents, and internal conversations. Without a structured system, leadership cannot reliably measure workload, pursuit quality, bottlenecks, pricing performance, or decision outcomes. | H11: Opportunity information often arrives through disconnected portals, emails, documents, and internal conversations. Without a structured system, leadership cannot reliably measure workload, pursuit quality, bottlenecks, pricing performance, or decision outcomes.
A13: MY APPROACH | B13: MY APPROACH | C13: MY APPROACH | D13: MY APPROACH | E13: MY APPROACH | F13: MY APPROACH | G13: MY APPROACH | H13: MY APPROACH
A14: I designed a single-source bid register with controlled statuses, structured risk fields, workflow timing, bid/no-bid reasoning, submission tracking, and post-bid intelligence. Each analytical view is driven from that shared architecture. | B14: I designed a single-source bid register with controlled statuses, structured risk fields, workflow timing, bid/no-bid reasoning, submission tracking, and post-bid intelligence. Each analytical view is driven from that shared architecture. | C14: I designed a single-source bid register with controlled statuses, structured risk fields, workflow timing, bid/no-bid reasoning, submission tracking, and post-bid intelligence. Each analytical view is driven from that shared architecture. | D14: I designed a single-source bid register with controlled statuses, structured risk fields, workflow timing, bid/no-bid reasoning, submission tracking, and post-bid intelligence. Each analytical view is driven from that shared architecture. | E14: I designed a single-source bid register with controlled statuses, structured risk fields, workflow timing, bid/no-bid reasoning, submission tracking, and post-bid intelligence. Each analytical view is driven from that shared architecture. | F14: I designed a single-source bid register with controlled statuses, structured risk fields, workflow timing, bid/no-bid reasoning, submission tracking, and post-bid intelligence. Each analytical view is driven from that shared architecture. | G14: I designed a single-source bid register with controlled statuses, structured risk fields, workflow timing, bid/no-bid reasoning, submission tracking, and post-bid intelligence. Each analytical view is driven from that shared architecture. | H14: I designed a single-source bid register with controlled statuses, structured risk fields, workflow timing, bid/no-bid reasoning, submission tracking, and post-bid intelligence. Each analytical view is driven from that shared architecture.
A15: I designed a single-source bid register with controlled statuses, structured risk fields, workflow timing, bid/no-bid reasoning, submission tracking, and post-bid intelligence. Each analytical view is driven from that shared architecture. | B15: I designed a single-source bid register with controlled statuses, structured risk fields, workflow timing, bid/no-bid reasoning, submission tracking, and post-bid intelligence. Each analytical view is driven from that shared architecture. | C15: I designed a single-source bid register with controlled statuses, structured risk fields, workflow timing, bid/no-bid reasoning, submission tracking, and post-bid intelligence. Each analytical view is driven from that shared architecture. | D15: I designed a single-source bid register with controlled statuses, structured risk fields, workflow timing, bid/no-bid reasoning, submission tracking, and post-bid intelligence. Each analytical view is driven from that shared architecture. | E15: I designed a single-source bid register with controlled statuses, structured risk fields, workflow timing, bid/no-bid reasoning, submission tracking, and post-bid intelligence. Each analytical view is driven from that shared architecture. | F15: I designed a single-source bid register with controlled statuses, structured risk fields, workflow timing, bid/no-bid reasoning, submission tracking, and post-bid intelligence. Each analytical view is driven from that shared architecture. | G15: I designed a single-source bid register with controlled statuses, structured risk fields, workflow timing, bid/no-bid reasoning, submission tracking, and post-bid intelligence. Each analytical view is driven from that shared architecture. | H15: I designed a single-source bid register with controlled statuses, structured risk fields, workflow timing, bid/no-bid reasoning, submission tracking, and post-bid intelligence. Each analytical view is driven from that shared architecture.
A17: SOLUTION | B17: SOLUTION | C17: SOLUTION | D17: SOLUTION | E17: SOLUTION | F17: SOLUTION | G17: SOLUTION | H17: SOLUTION
... A32: Recommended navigation: Executive Dashboard → Active Pipeline → Bid-No-Bid Intelligence → Post-Bid Analysis → Workflow Intelligence → Opportunity Detail. Use the blue selector cells and Excel filters to interact with the model. | B32: Recommended navigation: Executive Dashboard → Active Pipeline → Bid-No-Bid Intelligence → Post-Bid Analysis → Workflow Intelligence → Opportunity Detail. Use the blue selector cells and Excel filters to interact with the model. | C32: Recommended navigation: Executive Dashboard → Active Pipeline → Bid-No-Bid Intelligence → Post-Bid Analysis → Workflow Intelligence → Opportunity Detail. Use the blue selector cells and Excel filters to interact with the model. | D32: Recommended navigation: Executive Dashboard → Active Pipeline → Bid-No-Bid Intelligence → Post-Bid Analysis → Workflow Intelligence → Opportunity Detail. Use the blue selector cells and Excel filters to interact with the model. | E32: Recommended navigation: Executive Dashboard → Active Pipeline → Bid-No-Bid Intelligence → Post-Bid Analysis → Workflow Intelligence → Opportunity Detail. Use the blue selector cells and Excel filters to interact with the model. | F32: Recommended navigation: Executive Dashboard → Active Pipeline → Bid-No-Bid Intelligence → Post-Bid Analysis → Workflow Intelligence → Opportunity Detail. Use the blue selector cells and Excel filters to interact with the model. | G32: Recommended navigation: Executive Dashboard → Active Pipeline → Bid-No-Bid Intelligence → Post-Bid Analysis → Workflow Intelligence → Opportunity Detail. Use the blue selector cells and Excel filters to interact with the model. | H32: Recommended navigation: Executive Dashboard → Active Pipeline → Bid-No-Bid Intelligence → Post-Bid Analysis → Workflow Intelligence → Opportunity Detail. Use the blue selector cells and Excel filters to interact with the model.

Sheet 1. Opportunity Register
A1: Opportunity ID | B1: Opportunity | C1: Client | D1: Client Type | E1: Service | F1: Market | G1: Owner | H1: Identified Date | I1: Due Date | J1: Current Stage | K1: Outcome | L1: Approved Pursuit? | M1: Submitted? | N1: Est. Annual Value | O1: Est. Total Value | P1: Square Feet | Q1: Site Count | R1: Term (Months) | S1: Prevailing Wage? | T1: Bond Required? | U1: Risk Level | V1: No-Bid Reason | W1: Decision Notes | X1: Submitted Price | Y1: Winning Price | Z1: Winner | AA1: Incumbent | AB1: Review Days | AC1: Operational Review Days | AD1: Pricing Days | AE1: Proposal Days | AF1: Decision Date | AG1: Submitted Date | AH1: Award Date | AI1: Variance $ | AJ1: Variance % | AK1: Price / SF | AL1: Days to Decision | AM1: Proposal Turnaround | AN1: Next Action | AO1: Key Finding | AP1: Reporting Month
A2: BID-001 | B2: Daily Bugle Headquarters – Integrated Facility Operations | C2: Daily Bugle Headquarters | D2: Commercial | E2: Facility Maintenance | F2: Outer Region | G2: Michael Ngo | H2: 45902 | I2: 45920 | J2: Closed – No-Bid | K2: No-Bid | L2: No | M2: No | N2: 62400 | O2: 62400 | P2: 12000 | Q2: 1 | R2: 12 | S2: No | T2: No | U2: High | V2: Geographic Distance | W2: Declined because geographic distance reduced strategic or operational fit. | AA2: Atlas Building Partners | AB2: 1 | AC2: 7 | AD2: 0 | AE2: 0 | AF2: 45910 | AI2: =IF(OR(X2="",Y2=""),"",X2-Y2) | AJ2: =IFERROR((X2-Y2)/Y2,"") | AK2: =IFERROR(X2/P2,"") -> 0 | AL2: =IF(AF2="","",AF2-H2) -> 8 | AM2: =IF(AG2="","",AG2-AF2) | AN2: Document decision intelligence | AO2: Resources were preserved for better-aligned pursuits. | AP2: Sep 2025
A3: BID-002 | B3: Metropolis Community College – Districtwide Pest Prevention | C3: Metropolis Community College | D3: Education | E3: Pest Control | F3: Hudson Valley | G3: Avery Chen | H3: 45903 | I3: 45922 | J3: Closed – Awarded | K3: Lost | L3: Yes | M3: Yes | N3: 18000 | O3: 36000 | Q3: 8 | R3: 24 | S3: Yes | T3: No | U3: Low | W3: Pursuit aligned with the fictional bidder's service strategy; routine pursuit within demonstrated service and geographic capabilities. | X3: 36000 | Y3: 33000 | Z3: Wayne Municipal Services | AA3: Blue Lantern Services | AB3: 2 | AC3: 3 | AD3: 3 | AE3: 3 | AF3: 45908 | AG3: 45914 | AH3: 45941 | AI3: =IF(OR(X3="",Y3=""),"",X3-Y3) -> 3000 | AJ3: =IFERROR((X3-Y3)/Y3,"") -> 0.090909091 | AK3: =IFERROR(X3/P3,"") | AL3: =IF(AF3="","",AF3-H3) -> 5 | AM3: =IF(AG3="","",AG3-AF3) -> 6 | AN3: Request debrief or tabulation | AO3: Result provides a usable market benchmark for future pricing. | AP3: Sep 2025
A4: BID-003 | B4: Atlas County Services – Multi-Phase Final Clean | C4: Atlas County Services | D4: Government | E4: Post-Construction Cleaning | F4: Outer Region | G4: Jordan Ellis | H4: 45904 | I4: 45924 | J4: Closed – No-Bid | K4: No-Bid | L4: No | M4: No | N4: 68500 | O4: 205500 | P4: 87862 | Q4: 1 | R4: 36 | S4: Yes | T4: No | U4: Medium | V4: Geographic Distance | W4: Declined because geographic distance reduced strategic or operational fit. | AA4: Sentinel Operations | AB4: 3 | AC4: 4 | AD4: 0 | AE4: 0 | AF4: 45911 | AI4: =IF(OR(X4="",Y4=""),"",X4-Y4) | AJ4: =IFERROR((X4-Y4)/Y4,"") | AK4: =IFERROR(X4/P4,"") -> 0 | AL4: =IF(AF4="","",AF4-H4) -> 7 | AM4: =IF(AG4="","",AG4-AF4) | AN4: Document decision intelligence | AO4: Resources were preserved for better-aligned pursuits. | AP4: Sep 2025
A5: BID-004 | B5: Orbit Retail Properties – Municipal Buildings Custodial Services | C5: Orbit Retail Properties | D5: Commercial | E5: Custodial | F5: North Jersey | G5: Priya Shah | H5: 45905 | I5: 45926 | J5: Closed – Awarded | K5: Lost | L5: Yes | M5: Yes | N5: 320800 | O5: 320800 | P5: 125793 | Q5: 8 | R5: 12 | S5: No | T5: No | U5: Low | W5: Pursuit aligned with the fictional bidder's service strategy; routine pursuit within demonstrated service and geographic capabilities. | X5: 320800 | Y5: 286400 | Z5: Blue Lantern Services | AA5: Pinnacle Facility Care | AB5: 1 | AC5: 5 | AD5: 5 | AE5: 2 | AF5: 45911 | AG5: 45918 | AH5: 45947 | AI5: =IF(OR(X5="",Y5=""),"",X5-Y5) -> 34400 | AJ5: =IFERROR((X5-Y5)/Y5,"") -> 0.12011173 | AK5: =IFERROR(X5/P5,"") -> 2.5502214 | AL5: =IF(AF5="","",AF5-H5) -> 6 | AM5: =IF(AG5="","",AG5-AF5) -> 7 | AN5: Request debrief or tabulation | AO5: Result provides a usable market benchmark for future pricing. | AP5: Sep 2025
A6: BID-005 | B6: Stark Facilities Group – Grounds and Landscape Maintenance | C6: Stark Facilities Group | D6: Commercial | E6: Landscaping | F6: Central Jersey | G6: Michael Ngo | H6: 45906 | I6: 45928 | J6: Closed – No-Bid | K6: No-Bid | L6: No | M6: No | N6: 75300 | O6: 150600 | P6: 163724 | Q6: 1 | R6: 24 | S6: No | T6: No | U6: Low | V6: Insufficient Time | W6: Declined because insufficient time reduced strategic or operational fit. | AA6: Stark Facilities Group | AB6: 2 | AC6: 2 | AD6: 0 | AE6: 0 | AF6: 45910 | AI6: =IF(OR(X6="",Y6=""),"",X6-Y6) | AJ6: =IFERROR((X6-Y6)/Y6,"") | AK6: =IFERROR(X6/P6,"") -> 0 | AL6: =IF(AF6="","",AF6-H6) -> 4 | AM6: =IF(AG6="","",AG6-AF6) | AN6: Document decision intelligence | AO6: Resources were preserved for better-aligned pursuits. | AP6: Sep 2025
A7: BID-006 | B7: Atlas County Services – Multi-Site Evening Janitorial | C7: Atlas County Services | D7: Government | E7: Janitorial | F7: North Jersey | G7: Avery Chen | H7: 45937 | I7: 45960 | J7: Closed – Awarded | K7: Lost | L7: Yes | M7: Yes | N7: 453700 | O7: 1361100 | P7: 201655 | Q7: 8 | R7: 36 | S7: Yes | T7: Yes | U7: Low | W7: Pursuit aligned with the fictional bidder's service strategy; routine pursuit within demonstrated service and geographic capabilities. | X7: 1361100 | Y7: 1266100 | Z7: Pinnacle Facility Care | AA7: Wayne Municipal Services | AB7: 3 | AC7: 3 | AD7: 3 | AE7: 4 | AF7: 45943 | AG7: 45950 | AH7: 45983 | AI7: =IF(OR(X7="",Y7=""),"",X7-Y7) -> 95000 | AJ7: =IFERROR((X7-Y7)/Y7,"") -> 0.075033568 | AK7: =IFERROR(X7/P7,"") -> 6.7496467 | AL7: =IF(AF7="","",AF7-H7) -> 6 | AM7: =IF(AG7="","",AG7-AF7) -> 7 | AN7: Request debrief or tabulation | AO7: Result provides a usable market benchmark for future pricing. | AP7: Oct 2025
A8: BID-007 | B8: Orbit Retail Properties – Rodent Control Program | C8: Orbit Retail Properties | D8: Commercial | E8: Pest Control | F8: Central Jersey | G8: Jordan Ellis | H8: 45938 | I8: 45962 | J8: Closed – Awarded | K8: Lost | L8: Yes | M8: Yes | N8: 18000 | O8: 18000 | Q8: 1 | R8: 12 | S8: No | T8: No | U8: Low | W8: Pursuit aligned with the fictional bidder's service strategy; routine pursuit within demonstrated service and geographic capabilities. | X8: 18000 | Y8: 16500 | Z8: Stark Facilities Group | AA8: Atlas Building Partners | AB8: 1 | AC8: 4 | AD8: 4 | AE8: 2 | AF8: 45943 | AG8: 45949 | AH8: 45986 | AI8: =IF(OR(X8="",Y8=""),"",X8-Y8) -> 1500 | AJ8: =IFERROR((X8-Y8)/Y8,"") -> 0.090909091 | AK8: =IFERROR(X8/P8,"") | AL8: =IF(AF8="","",AF8-H8) -> 5 | AM8: =IF(AG8="","",AG8-AF8) -> 6 | AN8: Request debrief or tabulation | AO8: Result provides a usable market benchmark for future pricing. | AP8: Oct 2025
A9: BID-008 | B9: Stark Facilities Group – New Facility Turnover Cleaning | C9: Stark Facilities Group | D9: Commercial | E9: Post-Construction Cleaning | F9: Metro NY | G9: Priya Shah | H9: 45939 | I9: 45964 | J9: Closed – Awarded | K9: Lost | L9: Yes | M9: Yes | N9: 216500 | O9: 433000 | P9: 277517 | Q9: 8 | R9: 24 | S9: No | T9: No | U9: Low | W9: Pursuit aligned with the fictional bidder's service strategy; routine pursuit within demonstrated service and geographic capabilities. | X9: 433000 | Y9: 391900 | Z9: Wayne Municipal Services | AA9: Blue Lantern Services | AB9: 2 | AC9: 5 | AD9: 5 | AE9: 3 | AF9: 45946 | AG9: 45954 | AH9: 45989 | AI9: =IF(OR(X9="",Y9=""),"",X9-Y9) -> 41100 | AJ9: =IFERROR((X9-Y9)/Y9,"") -> 0.10487369 | AK9: =IFERROR(X9/P9,"") -> 1.5602648 | AL9: =IF(AF9="","",AF9-H9) -> 7 | AM9: =IF(AG9="","",AG9-AF9) -> 8 | AN9: Request debrief or tabulation | AO9: Result provides a usable market benchmark for future pricing. | AP9: Oct 2025
A10: BID-009 | B10: Parker Research Campus – Campus Custodial Services | C10: Parker Research Campus | D10: Commercial | E10: Custodial | F10: Hudson Valley | G10: Michael Ngo | H10: 45940 | I10: 45966 | J10: Closed – No-Bid | K10: No-Bid | L10: No | M10: No | N10: 804400 | O10: 2413200 | P10: 315448 | Q10: 1 | R10: 36 | S10: No | T10: No | U10: Low | V10: Scope Misalignment | W10: Declined because scope misalignment reduced strategic or operational fit. | AA10: Sentinel Operations | AB10: 3 | AC10: 2 | AD10: 0 | AE10: 0 | AF10: 45945 | AI10: =IF(OR(X10="",Y10=""),"",X10-Y10) | AJ10: =IFERROR((X10-Y10)/Y10,"") | AK10: =IFERROR(X10/P10,"") -> 0 | AL10: =IF(AF10="","",AF10-H10) -> 5 | AM10: =IF(AG10="","",AG10-AF10) | AN10: Document decision intelligence | AO10: Resources were preserved for better-aligned pursuits. | AP10: Oct 2025
A11: BID-010 | B11: Beacon Preparatory Schools – Seasonal Grounds Services | C11: Beacon Preparatory Schools | D11: Education | E11: Landscaping | F11: Outer Region | G11: Avery Chen | H11: 45941 | I11: 45968 | J11: Closed – No-Bid | K11: No-Bid | L11: No | M11: No | N11: 162600 | O11: 162600 | P11: 353379 | Q11: 8 | R11: 12 | S11: No | T11: No | U11: Medium | V11: Geographic Distance | W11: Declined because geographic distance reduced strategic or operational fit. | AA11: Pinnacle Facility Care | AB11: 1 | AC11: 3 | AD11: 0 | AE11: 0 | AF11: 45945 | AI11: =IF(OR(X11="",Y11=""),"",X11-Y11) | AJ11: =IFERROR((X11-Y11)/Y11,"") | AK11: =IFERROR(X11/P11,"") -> 0 | AL11: =IF(AF11="","",AF11-H11) -> 4 | AM11: =IF(AG11="","",AG11-AF11) | AN11: Document decision intelligence | AO11: Resources were preserved for better-aligned pursuits. | AP11: Oct 2025
A12: BID-011 | B12: Stark Facilities Group – Event Security Coverage | C12: Stark Facilities Group | D12: Commercial | E12: Security | F12: Hudson Valley | G12: Jordan Ellis | H12: 45973 | I12: 46001 | J12: Closed – Awarded | K12: Lost | L12: Yes | M12: Yes | N12: 170500 | O12: 341000 | Q12: 1 | R12: 24 | S12: No | T12: No | U12: High | W12: Pursuit aligned with the fictional bidder's service strategy; requires leadership review of operating model, compliance exposure, and staffing assumptions. | X12: 341000 | Y12: 289000 | Z12: Sentinel Operations | AA12: Stark Facilities Group | AB12: 2 | AC12: 7 | AD12: 4 | AE12: 3 | AF12: 45982 | AG12: 45989 | AH12: 46029 | AI12: =IF(OR(X12="",Y12=""),"",X12-Y12) -> 52000 | AJ12: =IFERROR((X12-Y12)/Y12,"") -> 0.1799308 | AK12: =IFERROR(X12/P12,"") | AL12: =IF(AF12="","",AF12-H12) -> 9 | AM12: =IF(AG12="","",AG12-AF12) -> 7 | AN12: Request debrief or tabulation | AO12: Result provides a usable market benchmark for future pricing. | AP12: Nov 2025
A13: BID-012 | B13: Parker Research Campus – Carpet and Floor Renewal | C13: Parker Research Campus | D13: Commercial | E13: Specialty Floor Care | F13: Outer Region | G13: Priya Shah | H13: 45974 | I13: 46003 | J13: Closed – No-Bid | K13: No-Bid | L13: No | M13: No | N13: 145900 | O13: 437700 | P13: 429241 | Q13: 8 | R13: 36 | S13: No | T13: No | U13: Medium | V13: Geographic Distance | W13: Declined because geographic distance reduced strategic or operational fit. | AA13: Wayne Municipal Services | AB13: 3 | AC13: 5 | AD13: 0 | AE13: 0 | AF13: 45982 | AI13: =IF(OR(X13="",Y13=""),"",X13-Y13) | AJ13: =IFERROR((X13-Y13)/Y13,"") | AK13: =IFERROR(X13/P13,"") -> 0 | AL13: =IF(AF13="","",AF13-H13) -> 8 | AM13: =IF(AG13="","",AG13-AF13) | AN13: Document decision intelligence | AO13: Resources were preserved for better-aligned pursuits. | AP13: Nov 2025
A14: BID-013 | B14: Beacon Preparatory Schools – Final Construction Cleaning | C14: Beacon Preparatory Schools | D14: Education | E14: Post-Construction Cleaning | F14: North Jersey | G14: Michael Ngo | H14: 45975 | I14: 46005 | J14: Closed – No-Bid | K14: No-Bid | L14: No | M14: No | N14: 364400 | O14: 364400 | P14: 467172 | Q14: 1 | R14: 12 | S14: No | T14: No | U14: Low | V14: Geographic Distance | W14: Declined because geographic distance reduced strategic or operational fit. | AA14: Atlas Building Partners | AB14: 1 | AC14: 2 | AD14: 0 | AE14: 0 | AF14: 45978 | AI14: =IF(OR(X14="",Y14=""),"",X14-Y14) | AJ14: =IFERROR((X14-Y14)/Y14,"") | AK14: =IFERROR(X14/P14,"") -> 0 | AL14: =IF(AF14="","",AF14-H14) -> 3 | AM14: =IF(AG14="","",AG14-AF14) | AN14: Document decision intelligence | AO14: Resources were preserved for better-aligned pursuits. | AP14: Nov 2025
A15: BID-014 | B15: Wayne Municipal Services – Technical Building Maintenance | C15: Wayne Municipal Services | D15: Government | E15: Facility Maintenance | F15: Central Jersey | G15: Avery Chen | H15: 45976 | I15: 46007 | J15: Closed – Awarded | K15: Lost | L15: Yes | M15: Yes | N15: 2626500 | O15: 5253000 | P15: 505103 | Q15: 8 | R15: 24 | S15: Yes | T15: Yes | U15: High | W15: Pursuit aligned with the fictional bidder's service strategy; requires leadership review of operating model, compliance exposure, and staffing assumptions. | X15: 5253000 | Y15: 4169000 | Z15: Wayne Municipal Services | AA15: Blue Lantern Services | AB15: 2 | AC15: 8 | AD15: 3 | AE15: 3 | AF15: 45986 | AG15: 45992 | AH15: 46038 | AI15: =IF(OR(X15="",Y15=""),"",X15-Y15) -> 1084000 | AJ15: =IFERROR((X15-Y15)/Y15,"") -> 0.26001439 | AK15: =IFERROR(X15/P15,"") -> 10.399859 | AL15: =IF(AF15="","",AF15-H15) -> 10 | AM15: =IF(AG15="","",AG15-AF15) -> 6 | AN15: Request debrief or tabulation | AO15: Price exceeded the market benchmark, suggesting conservative staffing or risk assumptions. | AP15: Nov 2025
A16: BID-015 | B16: Emerald City Administrative Center – Campus Landscape Program | C16: Emerald City Administrative Center | D16: Government | E16: Landscaping | F16: Metro NY | G16: Jordan Ellis | H16: 45977 | I16: 46009 | J16: Closed – Awarded | K16: Lost | L16: Yes | M16: Yes | N16: 249800 | O16: 749400 | P16: 543034 | Q16: 1 | R16: 36 | S16: Yes | T16: No | U16: Low | W16: Pursuit aligned with the fictional bidder's service strategy; routine pursuit within demonstrated service and geographic capabilities. | X16: 749400 | Y16: 657400 | Z16: Atlas Building Partners | AA16: Sentinel Operations | AB16: 3 | AC16: 4 | AD16: 4 | AE16: 4 | AF16: 45984 | AG16: 45992 | AH16: 46041 | AI16: =IF(OR(X16="",Y16=""),"",X16-Y16) -> 92000 | AJ16: =IFERROR((X16-Y16)/Y16,"") -> 0.13994524 | AK16: =IFERROR(X16/P16,"") -> 1.3800241 | AL16: =IF(AF16="","",AF16-H16) -> 7 | AM16: =IF(AG16="","",AG16-AF16) -> 8 | AN16: Request debrief or tabulation | AO16: Result provides a usable market benchmark for future pricing. | AP16: Nov 2025
A17: BID-016 | B17: Beacon Preparatory Schools – Public Offices Custodial Support | C17: Beacon Preparatory Schools | D17: Education | E17: Janitorial | F17: Central Jersey | G17: Priya Shah | H17: 46008 | I17: 46041 | J17: Closed – Awarded | K17: Lost | L17: Yes | M17: Yes | N17: 1307200 | O17: 1307200 | P17: 580965 | Q17: 8 | R17: 12 | S17: No | T17: Yes | U17: High | W17: Pursuit aligned with the fictional bidder's service strategy; requires leadership review of operating model, compliance exposure, and staffing assumptions. | X17: 1307200 | Y17: 1216000 | Z17: Blue Lantern Services | AA17: Pinnacle Facility Care | AB17: 1 | AC17: 5 | AD17: 5 | AE17: 2 | AF17: 46014 | AG17: 46021 | AH17: 46074 | AI17: =IF(OR(X17="",Y17=""),"",X17-Y17) -> 91200 | AJ17: =IFERROR((X17-Y17)/Y17,"") -> 0.075 | AK17: =IFERROR(X17/P17,"") -> 2.2500495 | AL17: =IF(AF17="","",AF17-H17) -> 6 | AM17: =IF(AG17="","",AG17-AF17) -> 7 | AN17: Request debrief or tabulation | AO17: Result provides a usable market benchmark for future pricing. | AP17: Dec 2025
A18: BID-017 | B18: Wayne Municipal Services – Integrated Pest Management | C18: Wayne Municipal Services | D18: Government | E18: Pest Control | F18: Metro NY | G18: Michael Ngo | H18: 46009 | I18: 46043 | J18: Closed – No-Bid | K18: No-Bid | L18: No | M18: No | N18: 18000 | O18: 36000 | Q18: 1 | R18: 24 | S18: Yes | T18: No | U18: Low | V18: Minimum Qualifications | W18: Declined because minimum qualifications reduced strategic or operational fit. | AA18: Stark Facilities Group | AB18: 2 | AC18: 2 | AD18: 0 | AE18: 0 | AF18: 46013 | AI18: =IF(OR(X18="",Y18=""),"",X18-Y18) | AJ18: =IFERROR((X18-Y18)/Y18,"") | AK18: =IFERROR(X18/P18,"") | AL18: =IF(AF18="","",AF18-H18) -> 4 | AM18: =IF(AG18="","",AG18-AF18) | AN18: Document decision intelligence | AO18: Resources were preserved for better-aligned pursuits. | AP18: Dec 2025
A19: BID-018 | B19: Emerald City Administrative Center – Renovation Closeout Cleaning | C19: Emerald City Administrative Center | D19: Government | E19: Post-Construction Cleaning | F19: Hudson Valley | G19: Avery Chen | H19: 46010 | I19: 46045 | J19: Closed – Awarded | K19: Lost | L19: Yes | M19: Yes | N19: 512300 | O19: 1536900 | P19: 656827 | Q19: 8 | R19: 36 | S19: Yes | T19: Yes | U19: Low | W19: Pursuit aligned with the fictional bidder's service strategy; routine pursuit within demonstrated service and geographic capabilities. | X19: 1536900 | Y19: 1390900 | Z19: Pinnacle Facility Care | AA19: Wayne Municipal Services | AB19: 3 | AC19: 3 | AD19: 3 | AE19: 4 | AF19: 46016 | AG19: 46023 | AH19: 46080 | AI19: =IF(OR(X19="",Y19=""),"",X19-Y19) -> 146000 | AJ19: =IFERROR((X19-Y19)/Y19,"") -> 0.10496801 | AK19: =IFERROR(X19/P19,"") -> 2.3398855 | AL19: =IF(AF19="","",AF19-H19) -> 6 | AM19: =IF(AG19="","",AG19-AF19) -> 7 | AN19: Request debrief or tabulation | AO19: Result provides a usable market benchmark for future pricing. | AP19: Dec 2025
A20: BID-019 | B20: Keystone Civic Complex – Civic Center Custodial Program | C20: Keystone Civic Complex | D20: Government | E20: Custodial | F20: Outer Region | G20: Jordan Ellis | H20: 45993 | I20: 46029 | J20: Closed – No-Bid | K20: No-Bid | L20: No | M20: No | N20: 1771600 | O20: 1771600 | P20: 694758 | Q20: 1 | R20: 12 | S20: No | T20: Yes | U20: High | V20: Geographic Distance | W20: Declined because geographic distance reduced strategic or operational fit. | AA20: Atlas Building Partners | AB20: 1 | AC20: 4 | AD20: 0 | AE20: 0 | AF20: 45998 | AI20: =IF(OR(X20="",Y20=""),"",X20-Y20) | AJ20: =IFERROR((X20-Y20)/Y20,"") | AK20: =IFERROR(X20/P20,"") -> 0 | AL20: =IF(AF20="","",AF20-H20) -> 5 | AM20: =IF(AG20="","",AG20-AF20) | AN20: Document decision intelligence | AO20: Resources were preserved for better-aligned pursuits. | AP20: Dec 2025
A21: BID-020 | B21: Gotham Public Schools – Municipal Grounds Care | C21: Gotham Public Schools | D21: Education | E21: Landscaping | F21: North Jersey | G21: Priya Shah | H21: 45994 | I21: 46031 | J21: Closed – Awarded | K21: Lost | L21: Yes | M21: Yes | N21: 337000 | O21: 674000 | P21: 732689 | Q21: 8 | R21: 24 | S21: Yes | T21: No | U21: Low | W21: Pursuit aligned with the fictional bidder's service strategy; routine pursuit within demonstrated service and geographic capabilities. | X21: 674000 | Y21: 591200 | Z21: Wayne Municipal Services | AA21: Blue Lantern Services | AB21: 2 | AC21: 5 | AD21: 5 | AE21: 3 | AF21: 46001 | AG21: 46009 | AH21: 46068 | AI21: =IF(OR(X21="",Y21=""),"",X21-Y21) -> 82800 | AJ21: =IFERROR((X21-Y21)/Y21,"") -> 0.14005413 | AK21: =IFERROR(X21/P21,"") -> 0.91989917 | AL21: =IF(AF21="","",AF21-H21) -> 7 | AM21: =IF(AG21="","",AG21-AF21) -> 8 | AN21: Request debrief or tabulation | AO21: Result provides a usable market benchmark for future pricing. | AP21: Dec 2025
A22: BID-021 | B22: Emerald City Administrative Center – Unarmed Guard Services | C22: Emerald City Administrative Center | D22: Government | E22: Security | F22: Outer Region | G22: Michael Ngo | H22: 46026 | I22: 46044 | J22: Closed – No-Bid | K22: No-Bid | L22: No | M22: No | N22: 170500 | O22: 511500 | Q22: 1 | R22: 36 | S22: Yes | T22: No | U22: High | V22: Geographic Distance | W22: Declined because geographic distance reduced strategic or operational fit. | AA22: Sentinel Operations | AB22: 3 | AC22: 8 | AD22: 0 | AE22: 0 | AF22: 46037 | AI22: =IF(OR(X22="",Y22=""),"",X22-Y22) | AJ22: =IFERROR((X22-Y22)/Y22,"") | AK22: =IFERROR(X22/P22,"") | AL22: =IF(AF22="","",AF22-H22) -> 11 | AM22: =IF(AG22="","",AG22-AF22) | AN22: Document decision intelligence | AO22: Resources were preserved for better-aligned pursuits. | AP22: Jan 2026
A23: BID-022 | B23: Keystone Civic Complex – Districtwide Pest Prevention | C23: Keystone Civic Complex | D23: Government | E23: Pest Control | F23: North Jersey | G23: Avery Chen | H23: 46027 | I23: 46046 | J23: Closed – Awarded | K23: Lost | L23: Yes | M23: Yes | N23: 18000 | O23: 18000 | Q23: 8 | R23: 12 | S23: No | T23: No | U23: Low | W23: Pursuit aligned with the fictional bidder's service strategy; routine pursuit within demonstrated service and geographic capabilities. | X23: 18000 | Y23: 16500 | Z23: Blue Lantern Services | AA23: Pinnacle Facility Care | AB23: 1 | AC23: 3 | AD23: 3 | AE23: 2 | AF23: 46031 | AG23: 46036 | AH23: 46085 | AI23: =IF(OR(X23="",Y23=""),"",X23-Y23) -> 1500 | AJ23: =IFERROR((X23-Y23)/Y23,"") -> 0.090909091 | AK23: =IFERROR(X23/P23,"") | AL23: =IF(AF23="","",AF23-H23) -> 4 | AM23: =IF(AG23="","",AG23-AF23) -> 5 | AN23: Request debrief or tabulation | AO23: Result provides a usable market benchmark for future pricing. | AP23: Jan 2026
A24: BID-023 | B24: Gotham Public Schools – Districtwide Floor Services | C24: Gotham Public Schools | D24: Education | E24: Specialty Floor Care | F24: Central Jersey | G24: Jordan Ellis | H24: 46028 | I24: 46048 | J24: Closed – Awarded | K24: Won | L24: Yes | M24: Yes | N24: 287800 | O24: 575600 | P24: 846482 | Q24: 1 | R24: 24 | S24: Yes | T24: No | U24: Low | W24: Pursuit aligned with the fictional bidder's service strategy; routine pursuit within demonstrated service and geographic capabilities. | X24: 575600 | Y24: 575600 | Z24: Michael BidWorks | AA24: Stark Facilities Group | AB24: 2 | AC24: 4 | AD24: 4 | AE24: 3 | AF24: 46034 | AG24: 46041 | AH24: 46088 | AI24: =IF(OR(X24="",Y24=""),"",X24-Y24) -> 0 | AJ24: =IFERROR((X24-Y24)/Y24,"") -> 0 | AK24: =IFERROR(X24/P24,"") -> 0.67999083 | AL24: =IF(AF24="","",AF24-H24) -> 6 | AM24: =IF(AG24="","",AG24-AF24) -> 7 | AN24: Prepare transition brief | AO24: Competitive positioning and scope fit supported award. | AP24: Jan 2026
A25: BID-024 | B25: Northstar Charter Network – Municipal Buildings Custodial Services | C25: Northstar Charter Network | D25: Education | E25: Custodial | F25: Metro NY | G25: Priya Shah | H25: 46029 | I25: 46050 | J25: Closed – Awarded | K25: Lost | L25: Yes | M25: Yes | N25: 2255300 | O25: 6765900 | P25: 884413 | Q25: 8 | R25: 36 | S25: Yes | T25: Yes | U25: High | W25: Pursuit aligned with the fictional bidder's service strategy; requires leadership review of operating model, compliance exposure, and staffing assumptions. | X25: 6765900 | Y25: 6041000 | Z25: Pinnacle Facility Care | AA25: Wayne Municipal Services | AB25: 3 | AC25: 5 | AD25: 5 | AE25: 4 | AF25: 46037 | AG25: 46046 | AH25: 46091 | AI25: =IF(OR(X25="",Y25=""),"",X25-Y25) -> 724900 | AJ25: =IFERROR((X25-Y25)/Y25,"") -> 0.11999669 | AK25: =IFERROR(X25/P25,"") -> 7.6501589 | AL25: =IF(AF25="","",AF25-H25) -> 8 | AM25: =IF(AG25="","",AG25-AF25) -> 9 | AN25: Request debrief or tabulation | AO25: Result provides a usable market benchmark for future pricing. | AP25: Jan 2026
A26: BID-025 | B26: Harborlight Medical Offices – Grounds and Landscape Maintenance | C26: Harborlight Medical Offices | D26: Commercial | E26: Landscaping | F26: Hudson Valley | G26: Michael Ngo | H26: 46030 | I26: 46052 | J26: Closed – No-Bid | K26: No-Bid | L26: No | M26: No | N26: 18000 | O26: 18000 | P26: 32344 | Q26: 1 | R26: 12 | S26: No | T26: No | U26: Low | V26: Geographic Distance | W26: Declined because geographic distance reduced strategic or operational fit. | AA26: Atlas Building Partners | AB26: 1 | AC26: 2 | AD26: 0 | AE26: 0 | AF26: 46033 | AI26: =IF(OR(X26="",Y26=""),"",X26-Y26) | AJ26: =IFERROR((X26-Y26)/Y26,"") | AK26: =IFERROR(X26/P26,"") -> 0 | AL26: =IF(AF26="","",AF26-H26) -> 3 | AM26: =IF(AG26="","",AG26-AF26) | AN26: Document decision intelligence | AO26: Resources were preserved for better-aligned pursuits. | AP26: Jan 2026
A27: BID-026 | B27: Gotham Public Schools – Multi-Site Evening Janitorial | C27: Gotham Public Schools | D27: Education | E27: Janitorial | F27: Metro NY | G27: Avery Chen | H27: 46062 | I27: 46085 | J27: Closed – Awarded | K27: Won | L27: Yes | M27: Yes | N27: 158100 | O27: 316200 | P27: 70275 | Q27: 8 | R27: 24 | S27: Yes | T27: No | U27: Low | W27: Pursuit aligned with the fictional bidder's service strategy; routine pursuit within demonstrated service and geographic capabilities. | X27: 316200 | Y27: 316200 | Z27: Michael BidWorks | AA27: Blue Lantern Services | AB27: 2 | AC27: 3 | AD27: 3 | AE27: 3 | AF27: 46067 | AG27: 46073 | AH27: 46128 | AI27: =IF(OR(X27="",Y27=""),"",X27-Y27) -> 0 | AJ27: =IFERROR((X27-Y27)/Y27,"") -> 0 | AK27: =IFERROR(X27/P27,"") -> 4.4994664 | AL27: =IF(AF27="","",AF27-H27) -> 5 | AM27: =IF(AG27="","",AG27-AF27) -> 6 | AN27: Prepare transition brief | AO27: Competitive positioning and scope fit supported award. | AP27: Feb 2026
A28: BID-027 | B28: Northstar Charter Network – Multi-Site Facility Services | C28: Northstar Charter Network | D28: Education | E28: Facility Maintenance | F28: Hudson Valley | G28: Jordan Ellis | H28: 46063 | I28: 46087 | J28: Closed – Awarded | K28: Lost | L28: Yes | M28: Yes | N28: 562700 | O28: 1688100 | P28: 108206 | Q28: 1 | R28: 36 | S28: Yes | T28: Yes | U28: High | W28: Pursuit aligned with the fictional bidder's service strategy; requires leadership review of operating model, compliance exposure, and staffing assumptions. | X28: 1688100 | Y28: 1339800 | Z28: Atlas Building Partners | AA28: Sentinel Operations | AB28: 3 | AC28: 9 | AD28: 4 | AE28: 4 | AF28: 46075 | AG28: 46083 | AH28: 46131 | AI28: =IF(OR(X28="",Y28=""),"",X28-Y28) -> 348300 | AJ28: =IFERROR((X28-Y28)/Y28,"") -> 0.25996417 | AK28: =IFERROR(X28/P28,"") -> 15.600798 | AL28: =IF(AF28="","",AF28-H28) -> 12 | AM28: =IF(AG28="","",AG28-AF28) -> 8 | AN28: Request debrief or tabulation | AO28: Price exceeded the market benchmark, suggesting conservative staffing or risk assumptions. | AP28: Feb 2026
A29: BID-028 | B29: Harborlight Medical Offices – New Facility Turnover Cleaning | C29: Harborlight Medical Offices | D29: Commercial | E29: Post-Construction Cleaning | F29: Outer Region | G29: Priya Shah | H29: 46064 | I29: 46089 | J29: Closed – No-Bid | K29: No-Bid | L29: No | M29: No | N29: 114000 | O29: 114000 | P29: 146137 | Q29: 8 | R29: 12 | S29: No | T29: No | U29: Medium | V29: Geographic Distance | W29: Declined because geographic distance reduced strategic or operational fit. | AA29: Pinnacle Facility Care | AB29: 1 | AC29: 5 | AD29: 0 | AE29: 0 | AF29: 46070 | AI29: =IF(OR(X29="",Y29=""),"",X29-Y29) | AJ29: =IFERROR((X29-Y29)/Y29,"") | AK29: =IFERROR(X29/P29,"") -> 0 | AL29: =IF(AF29="","",AF29-H29) -> 6 | AM29: =IF(AG29="","",AG29-AF29) | AN29: Document decision intelligence | AO29: Resources were preserved for better-aligned pursuits. | AP29: Feb 2026
A30: BID-029 | B30: Queensboro Transit Authority – Campus Custodial Services | C30: Queensboro Transit Authority | D30: Government | E30: Custodial | F30: North Jersey | G30: Michael Ngo | H30: 46065 | I30: 46091 | J30: Closed – No-Bid | K30: No-Bid | L30: No | M30: No | N30: 469400 | O30: 938800 | P30: 184068 | Q30: 1 | R30: 24 | S30: Yes | T30: No | U30: Low | V30: Minimum Qualifications | W30: Declined because minimum qualifications reduced strategic or operational fit. | AA30: Stark Facilities Group | AB30: 2 | AC30: 2 | AD30: 0 | AE30: 0 | AF30: 46069 | AI30: =IF(OR(X30="",Y30=""),"",X30-Y30) | AJ30: =IFERROR((X30-Y30)/Y30,"") | AK30: =IFERROR(X30/P30,"") -> 0 | AL30: =IF(AF30="","",AF30-H30) -> 4 | AM30: =IF(AG30="","",AG30-AF30) | AN30: Document decision intelligence | AO30: Resources were preserved for better-aligned pursuits. | AP30: Feb 2026
A31: BID-030 | B31: Arcadia Housing Authority – Seasonal Grounds Services | C31: Arcadia Housing Authority | D31: Government | E31: Landscaping | F31: Central Jersey | G31: Avery Chen | H31: 46066 | I31: 46093 | J31: Closed – Awarded | K31: Lost | L31: Yes | M31: Yes | N31: 102100 | O31: 306300 | P31: 221999 | Q31: 8 | R31: 36 | S31: Yes | T31: No | U31: Low | W31: Pursuit aligned with the fictional bidder's service strategy; routine pursuit within demonstrated service and geographic capabilities. | X31: 306300 | Y31: 268700 | Z31: Pinnacle Facility Care | AA31: Wayne Municipal Services | AB31: 3 | AC31: 3 | AD31: 3 | AE31: 4 | AF31: 46072 | AG31: 46079 | AH31: 46140 | AI31: =IF(OR(X31="",Y31=""),"",X31-Y31) -> 37600 | AJ31: =IFERROR((X31-Y31)/Y31,"") -> 0.13993301 | AK31: =IFERROR(X31/P31,"") -> 1.3797359 | AL31: =IF(AF31="","",AF31-H31) -> 6 | AM31: =IF(AG31="","",AG31-AF31) -> 7 | AN31: Request debrief or tabulation | AO31: Result provides a usable market benchmark for future pricing. | AP31: Feb 2026
A32: BID-031 | B32: Harborlight Medical Offices – Event Security Coverage | C32: Harborlight Medical Offices | D32: Commercial | E32: Security | F32: North Jersey | G32: Jordan Ellis | H32: 46095 | I32: 46123 | J32: Closed – No-Bid | K32: No-Bid | L32: No | M32: No | N32: 170500 | O32: 170500 | Q32: 1 | R32: 12 | S32: No | T32: No | U32: High | V32: Licensing Requirement | W32: Declined because licensing requirement reduced strategic or operational fit. | AA32: Atlas Building Partners | AB32: 1 | AC32: 6 | AD32: 0 | AE32: 0 | AF32: 46102 | AI32: =IF(OR(X32="",Y32=""),"",X32-Y32) | AJ32: =IFERROR((X32-Y32)/Y32,"") | AK32: =IFERROR(X32/P32,"") | AL32: =IF(AF32="","",AF32-H32) -> 7 | AM32: =IF(AG32="","",AG32-AF32) | AN32: Document decision intelligence | AO32: Resources were preserved for better-aligned pursuits. | AP32: Mar 2026
A33: BID-032 | B33: Queensboro Transit Authority – Commercial IPM Services | C33: Queensboro Transit Authority | D33: Government | E33: Pest Control | F33: Central Jersey | G33: Priya Shah | H33: 46096 | I33: 46125 | J33: Closed – Awarded | K33: Lost | L33: Yes | M33: Yes | N33: 18000 | O33: 36000 | Q33: 8 | R33: 24 | S33: Yes | T33: No | U33: Low | W33: Pursuit aligned with the fictional bidder's service strategy; routine pursuit within demonstrated service and geographic capabilities. | X33: 36000 | Y33: 33000 | Z33: Wayne Municipal Services | AA33: Blue Lantern Services | AB33: 2 | AC33: 5 | AD33: 5 | AE33: 3 | AF33: 46103 | AG33: 46111 | AH33: 46144 | AI33: =IF(OR(X33="",Y33=""),"",X33-Y33) -> 3000 | AJ33: =IFERROR((X33-Y33)/Y33,"") -> 0.090909091 | AK33: =IFERROR(X33/P33,"") | AL33: =IF(AF33="","",AF33-H33) -> 7 | AM33: =IF(AG33="","",AG33-AF33) -> 8 | AN33: Request debrief or tabulation | AO33: Result provides a usable market benchmark for future pricing. | AP33: Mar 2026
A34: BID-033 | B34: Arcadia Housing Authority – Final Construction Cleaning | C34: Arcadia Housing Authority | D34: Government | E34: Post-Construction Cleaning | F34: Metro NY | G34: Michael Ngo | H34: 46097 | I34: 46127 | J34: Closed – No-Bid | K34: No-Bid | L34: No | M34: No | N34: 261900 | O34: 785700 | P34: 335792 | Q34: 1 | R34: 36 | S34: Yes | T34: No | U34: Low | V34: Staffing / Operations Capacity | W34: Declined because staffing / operations capacity reduced strategic or operational fit. | AA34: Sentinel Operations | AB34: 3 | AC34: 2 | AD34: 0 | AE34: 0 | AF34: 46102 | AI34: =IF(OR(X34="",Y34=""),"",X34-Y34) | AJ34: =IFERROR((X34-Y34)/Y34,"") | AK34: =IFERROR(X34/P34,"") -> 0 | AL34: =IF(AF34="","",AF34-H34) -> 5 | AM34: =IF(AG34="","",AG34-AF34) | AN34: Document decision intelligence | AO34: Resources were preserved for better-aligned pursuits. | AP34: Mar 2026
A35: BID-034 | B35: Crescent Bay University – Stone and Resilient Floor Care | C35: Crescent Bay University | D35: Education | E35: Specialty Floor Care | F35: Hudson Valley | G35: Avery Chen | H35: 46098 | I35: 46129 | J35: Closed – Awarded | K35: Won | L35: Yes | M35: Yes | N35: 127100 | O35: 127100 | P35: 373723 | Q35: 8 | R35: 12 | S35: No | T35: No | U35: Low | W35: Pursuit aligned with the fictional bidder's service strategy; routine pursuit within demonstrated service and geographic capabilities. | X35: 127100 | Y35: 127100 | Z35: Michael BidWorks | AA35: Pinnacle Facility Care | AB35: 1 | AC35: 3 | AD35: 3 | AE35: 2 | AF35: 46102 | AG35: 46107 | AH35: 46150 | AI35: =IF(OR(X35="",Y35=""),"",X35-Y35) -> 0 | AJ35: =IFERROR((X35-Y35)/Y35,"") -> 0 | AK35: =IFERROR(X35/P35,"") -> 0.34009146 | AL35: =IF(AF35="","",AF35-H35) -> 4 | AM35: =IF(AG35="","",AG35-AF35) -> 5 | AN35: Prepare transition brief | AO35: Competitive positioning and scope fit supported award. | AP35: Mar 2026
A36: BID-035 | B36: Daily Bugle Headquarters – Campus Landscape Program | C36: Daily Bugle Headquarters | D36: Commercial | E36: Landscaping | F36: Outer Region | G36: Jordan Ellis | H36: 46099 | I36: 46131 | J36: Closed – No-Bid | K36: No-Bid | L36: No | M36: No | N36: 189400 | O36: 378800 | P36: 411654 | Q36: 1 | R36: 24 | S36: No | T36: No | U36: Medium | V36: Geographic Distance | W36: Declined because geographic distance reduced strategic or operational fit. | AA36: Stark Facilities Group | AB36: 2 | AC36: 4 | AD36: 0 | AE36: 0 | AF36: 46105 | AI36: =IF(OR(X36="",Y36=""),"",X36-Y36) | AJ36: =IFERROR((X36-Y36)/Y36,"") | AK36: =IFERROR(X36/P36,"") -> 0 | AL36: =IF(AF36="","",AF36-H36) -> 6 | AM36: =IF(AG36="","",AG36-AF36) | AN36: Document decision intelligence | AO36: Resources were preserved for better-aligned pursuits. | AP36: Mar 2026
A37: BID-036 | B37: Arcadia Housing Authority – Public Offices Custodial Support | C37: Arcadia Housing Authority | D37: Government | E37: Janitorial | F37: Hudson Valley | G37: Priya Shah | H37: 46131 | I37: 46164 | J37: Closed – Awarded | K37: Lost | L37: Yes | M37: Yes | N37: 1011600 | O37: 3034800 | P37: 449585 | Q37: 8 | R37: 36 | S37: Yes | T37: Yes | U37: Low | W37: Pursuit aligned with the fictional bidder's service strategy; routine pursuit within demonstrated service and geographic capabilities. | X37: 3034800 | Y37: 2823100 | Z37: Pinnacle Facility Care | AA37: Wayne Municipal Services | AB37: 3 | AC37: 5 | AD37: 5 | AE37: 4 | AF37: 46139 | AG37: 46148 | AH37: 46187 | AI37: =IF(OR(X37="",Y37=""),"",X37-Y37) -> 211700 | AJ37: =IFERROR((X37-Y37)/Y37,"") -> 0.074988488 | AK37: =IFERROR(X37/P37,"") -> 6.7502252 | AL37: =IF(AF37="","",AF37-H37) -> 8 | AM37: =IF(AG37="","",AG37-AF37) -> 9 | AN37: Request debrief or tabulation | AO37: Result provides a usable market benchmark for future pricing. | AP37: Apr 2026
A38: BID-037 | B38: Crescent Bay University – Integrated Pest Management | C38: Crescent Bay University | D38: Education | E38: Pest Control | F38: Outer Region | G38: Michael Ngo | H38: 46114 | I38: 46148 | J38: Closed – No-Bid | K38: No-Bid | L38: No | M38: No | N38: 18000 | O38: 18000 | Q38: 1 | R38: 12 | S38: No | T38: No | U38: Medium | V38: Geographic Distance | W38: Declined because geographic distance reduced strategic or operational fit. | AA38: Atlas Building Partners | AB38: 1 | AC38: 2 | AD38: 0 | AE38: 0 | AF38: 46117 | AI38: =IF(OR(X38="",Y38=""),"",X38-Y38) | AJ38: =IFERROR((X38-Y38)/Y38,"") | AK38: =IFERROR(X38/P38,"") | AL38: =IF(AF38="","",AF38-H38) -> 3 | AM38: =IF(AG38="","",AG38-AF38) | AN38: Document decision intelligence | AO38: Resources were preserved for better-aligned pursuits. | AP38: Apr 2026
A39: BID-038 | B39: Daily Bugle Headquarters – Renovation Closeout Cleaning | C39: Daily Bugle Headquarters | D39: Commercial | E39: Post-Construction Cleaning | F39: North Jersey | G39: Avery Chen | H39: 46115 | I39: 46150 | J39: Closed – Awarded | K39: Lost | L39: Yes | M39: Yes | N39: 409800 | O39: 819600 | P39: 525447 | Q39: 8 | R39: 24 | S39: No | T39: No | U39: Low | W39: Pursuit aligned with the fictional bidder's service strategy; routine pursuit within demonstrated service and geographic capabilities. | X39: 819600 | Y39: 741700 | Z39: Wayne Municipal Services | AA39: Blue Lantern Services | AB39: 2 | AC39: 3 | AD39: 3 | AE39: 3 | AF39: 46120 | AG39: 46126 | AH39: 46175 | AI39: =IF(OR(X39="",Y39=""),"",X39-Y39) -> 77900 | AJ39: =IFERROR((X39-Y39)/Y39,"") -> 0.10502899 | AK39: =IFERROR(X39/P39,"") -> 1.5598148 | AL39: =IF(AF39="","",AF39-H39) -> 5 | AM39: =IF(AG39="","",AG39-AF39) -> 6 | AN39: Request debrief or tabulation | AO39: Result provides a usable market benchmark for future pricing. | AP39: Apr 2026
A40: BID-039 | B40: Metropolis Community College – Civic Center Custodial Program | C40: Metropolis Community College | D40: Education | E40: Custodial | F40: Central Jersey | G40: Jordan Ellis | H40: 46116 | I40: 46152 | J40: Closed – Awarded | K40: Lost | L40: Yes | M40: Yes | N40: 1436600 | O40: 4309800 | P40: 563378 | Q40: 1 | R40: 36 | S40: Yes | T40: Yes | U40: High | W40: Pursuit aligned with the fictional bidder's service strategy; requires leadership review of operating model, compliance exposure, and staffing assumptions. | X40: 4309800 | Y40: 3848000 | Z40: Atlas Building Partners | AA40: Sentinel Operations | AB40: 3 | AC40: 4 | AD40: 4 | AE40: 4 | AF40: 46123 | AG40: 46131 | AH40: 46178 | AI40: =IF(OR(X40="",Y40=""),"",X40-Y40) -> 461800 | AJ40: =IFERROR((X40-Y40)/Y40,"") -> 0.1200104 | AK40: =IFERROR(X40/P40,"") -> 7.649926 | AL40: =IF(AF40="","",AF40-H40) -> 7 | AM40: =IF(AG40="","",AG40-AF40) -> 8 | AN40: Request debrief or tabulation | AO40: Result provides a usable market benchmark for future pricing. | AP40: Apr 2026
...

Sheet 2. Executive Dashboard
A1: EXECUTIVE BID INTELLIGENCE | B1: EXECUTIVE BID INTELLIGENCE | C1: EXECUTIVE BID INTELLIGENCE | D1: EXECUTIVE BID INTELLIGENCE | E1: EXECUTIVE BID INTELLIGENCE | F1: EXECUTIVE BID INTELLIGENCE | G1: EXECUTIVE BID INTELLIGENCE | H1: EXECUTIVE BID INTELLIGENCE | I1: EXECUTIVE BID INTELLIGENCE | J1: EXECUTIVE BID INTELLIGENCE | K1: EXECUTIVE BID INTELLIGENCE | L1: EXECUTIVE BID INTELLIGENCE | M1: EXECUTIVE BID INTELLIGENCE | N1: EXECUTIVE BID INTELLIGENCE
A2: Portfolio-wide performance, pipeline value, and pursuit outcomes | Fictional demonstration | B2: Portfolio-wide performance, pipeline value, and pursuit outcomes | Fictional demonstration | C2: Portfolio-wide performance, pipeline value, and pursuit outcomes | Fictional demonstration | D2: Portfolio-wide performance, pipeline value, and pursuit outcomes | Fictional demonstration | E2: Portfolio-wide performance, pipeline value, and pursuit outcomes | Fictional demonstration | F2: Portfolio-wide performance, pipeline value, and pursuit outcomes | Fictional demonstration | G2: Portfolio-wide performance, pipeline value, and pursuit outcomes | Fictional demonstration | H2: Portfolio-wide performance, pipeline value, and pursuit outcomes | Fictional demonstration | I2: Portfolio-wide performance, pipeline value, and pursuit outcomes | Fictional demonstration | J2: Portfolio-wide performance, pipeline value, and pursuit outcomes | Fictional demonstration | K2: Portfolio-wide performance, pipeline value, and pursuit outcomes | Fictional demonstration | L2: Portfolio-wide performance, pipeline value, and pursuit outcomes | Fictional demonstration | M2: Portfolio-wide performance, pipeline value, and pursuit outcomes | Fictional demonstration | N2: Portfolio-wide performance, pipeline value, and pursuit outcomes | Fictional demonstration
A3: Reporting Period | B3: Reporting Period | C3: All Periods | D3: All Periods | E3: ← Click for Drop Down
A5: OPPORTUNITIES REVIEWED | B5: OPPORTUNITIES REVIEWED | D5: SUBMITTED | E5: SUBMITTED | G5: WINS | H5: WINS | J5: NO-BIDS | K5: NO-BIDS | M5: DECIDED WIN RATE | N5: DECIDED WIN RATE
A6: =IF($C$3="All Periods",COUNTA('1. Opportunity Register'!$A$2:$A$61),COUNTIF('1. Opportunity Register'!$AP$2:$AP$61,$C$3)) -> 60 | D6: =IF($C$3="All Periods",COUNTIF('1. Opportunity Register'!$M$2:$M$61,"Yes"),COUNTIFS('1. Opportunity Register'!$M$2:$M$61,"Yes",'1. Opportunity Register'!$AP$2:$AP$61,$C$3)) -> 33 | G6: =IF($C$3="All Periods",COUNTIF('1. Opportunity Register'!$K$2:$K$61,"Won"),COUNTIFS('1. Opportunity Register'!$K$2:$K$61,"Won",'1. Opportunity Register'!$AP$2:$AP$61,$C$3)) -> 3 | J6: =IF($C$3="All Periods",COUNTIF('1. Opportunity Register'!$K$2:$K$61,"No-Bid"),COUNTIFS('1. Opportunity Register'!$K$2:$K$61,"No-Bid",'1. Opportunity Register'!$AP$2:$AP$61,$C$3)) -> 23 | M6: =IFERROR(G6/(G6+IF($C$3="All Periods",COUNTIF('1. Opportunity Register'!$K$2:$K$61,"Lost"),COUNTIFS('1. Opportunity Register'!$K$2:$K$61,"Lost",'1. Opportunity Register'!$AP$2:$AP$61,$C$3))),0) -> 0.10344828
A9: SUBMITTED VALUE | B9: SUBMITTED VALUE | C9: SUBMITTED VALUE | E9: ACTIVE PIPELINE VALUE | F9: ACTIVE PIPELINE VALUE | G9: ACTIVE PIPELINE VALUE | I9: AVERAGE CONTRACT VALUE | J9: AVERAGE CONTRACT VALUE | K9: AVERAGE CONTRACT VALUE | M9: AWAITING AWARD | N9: AWAITING AWARD
A10: =IF($C$3="All Periods",SUM('1. Opportunity Register'!$X$2:$X$61),SUMIFS('1. Opportunity Register'!$X$2:$X$61,'1. Opportunity Register'!$AP$2:$AP$61,$C$3)) -> 36813700 | E10: =IF($C$3="All Periods",SUMIFS('1. Opportunity Register'!$O$2:$O$61,'1. Opportunity Register'!$K$2:$K$61,"In Progress")+SUMIFS('1. Opportunity Register'!$O$2:$O$61,'1. Opportunity Register'!$K$2:$K$61,"Submitted")+SUMIFS('1. Opportunity Register'!$O$2:$O$61,'1. Opportunity Register'!$K$2:$K$61,"Awaiting Award"),SUMIFS('1. Opportunity Register'!$O$2:$O$61,'1. Opportunity Register'!$AP$2:$AP$61,$C$3,'1. Opportunity Register'!$K$2:$K$61,"In Progress")+SUMIFS('1. Opportunity Register'!$O$2:$O$61,'1. Opportunity Register'!$AP$2:$AP$61,$C$3,'1. Opportunity Register'!$K$2:$K$61,"Submitted")+SUMIFS('1. Opportunity Register'!$O$2:$O$61,'1. Opportunity Register'!$AP$2:$AP$61,$C$3,'1. Opportunity Register'!$K$2:$K$61,"Awaiting Award")) -> 7538300 | I10: =IFERROR(IF($C$3="All Periods",AVERAGEIF('1. Opportunity Register'!$O$2:$O$61,">0"),SUMIFS('1. Opportunity Register'!$O$2:$O$61,'1. Opportunity Register'!$AP$2:$AP$61,$C$3)/COUNTIF('1. Opportunity Register'!$AP$2:$AP$61,$C$3)),0) -> 958906.67 | M10: =IF($C$3="All Periods",COUNTIF('1. Opportunity Register'!$K$2:$K$61,"Awaiting Award"),COUNTIFS('1. Opportunity Register'!$K$2:$K$61,"Awaiting Award",'1. Opportunity Register'!$AP$2:$AP$61,$C$3)) -> 2
A30: Month | B30: Reviewed | C30: Submitted | D30: Wins | E30: No-Bids | G30: Outcome | H30: Count
A31: Sep 2025 | B31: =IF(OR($C$3="All Periods",$C$3=A31),COUNTIF('1. Opportunity Register'!$AP$2:$AP$61,A31),"") -> 5 | C31: =IF(OR($C$3="All Periods",$C$3=A31),COUNTIFS('1. Opportunity Register'!$M$2:$M$61,"Yes",'1. Opportunity Register'!$AP$2:$AP$61,A31),"") -> 2 | D31: =IF(OR($C$3="All Periods",$C$3=A31),COUNTIFS('1. Opportunity Register'!$K$2:$K$61,"Won",'1. Opportunity Register'!$AP$2:$AP$61,A31),"") -> 0 | E31: =IF(OR($C$3="All Periods",$C$3=A31),COUNTIFS('1. Opportunity Register'!$K$2:$K$61,"No-Bid",'1. Opportunity Register'!$AP$2:$AP$61,A31),"") -> 3 | G31: Won | H31: =IF($C$3="All Periods",COUNTIF('1. Opportunity Register'!$K$2:$K$61,G31),COUNTIFS('1. Opportunity Register'!$K$2:$K$61,G31,'1. Opportunity Register'!$AP$2:$AP$61,$C$3)) -> 3
A32: Oct 2025 | B32: =IF(OR($C$3="All Periods",$C$3=A32),COUNTIF('1. Opportunity Register'!$AP$2:$AP$61,A32),"") -> 5 | C32: =IF(OR($C$3="All Periods",$C$3=A32),COUNTIFS('1. Opportunity Register'!$M$2:$M$61,"Yes",'1. Opportunity Register'!$AP$2:$AP$61,A32),"") -> 3 | D32: =IF(OR($C$3="All Periods",$C$3=A32),COUNTIFS('1. Opportunity Register'!$K$2:$K$61,"Won",'1. Opportunity Register'!$AP$2:$AP$61,A32),"") -> 0 | E32: =IF(OR($C$3="All Periods",$C$3=A32),COUNTIFS('1. Opportunity Register'!$K$2:$K$61,"No-Bid",'1. Opportunity Register'!$AP$2:$AP$61,A32),"") -> 2 | G32: Lost | H32: =IF($C$3="All Periods",COUNTIF('1. Opportunity Register'!$K$2:$K$61,G32),COUNTIFS('1. Opportunity Register'!$K$2:$K$61,G32,'1. Opportunity Register'!$AP$2:$AP$61,$C$3)) -> 26
A33: Nov 2025 | B33: =IF(OR($C$3="All Periods",$C$3=A33),COUNTIF('1. Opportunity Register'!$AP$2:$AP$61,A33),"") -> 5 | C33: =IF(OR($C$3="All Periods",$C$3=A33),COUNTIFS('1. Opportunity Register'!$M$2:$M$61,"Yes",'1. Opportunity Register'!$AP$2:$AP$61,A33),"") -> 3 | D33: =IF(OR($C$3="All Periods",$C$3=A33),COUNTIFS('1. Opportunity Register'!$K$2:$K$61,"Won",'1. Opportunity Register'!$AP$2:$AP$61,A33),"") -> 0 | E33: =IF(OR($C$3="All Periods",$C$3=A33),COUNTIFS('1. Opportunity Register'!$K$2:$K$61,"No-Bid",'1. Opportunity Register'!$AP$2:$AP$61,A33),"") -> 2 | G33: No-Bid | H33: =IF($C$3="All Periods",COUNTIF('1. Opportunity Register'!$K$2:$K$61,G33),COUNTIFS('1. Opportunity Register'!$K$2:$K$61,G33,'1. Opportunity Register'!$AP$2:$AP$61,$C$3)) -> 23
